Workbook

Sheet Damage Calculator
A1: Buffed stats calculator
A2: Phys Atk | B2: 36779 | F2: Advance Blessing | H2: 0 | J2: Boss Atk food | K2: 0 | M2: Phys/Mag Atk | N2: =B2 -> 36779
A3: Phys/Mag Atk % | B3: 1.2048 | F3: Speed Infusion (Bucc buff) | H3: 0 | J3: Phys/MA Atk food | K3: 0 | M3: Phys/Mag Atk % | N3: =(B3+K3+35%*H2+15%*H6+21%*H4+10%*K11+G13) -> 1.2048
A4: Phys/Mag Dmg % | B4: 1.261 | F4: Unmanaged Anger (Hero buff) | H4: 0 | J4: Candy Basket / Cane | K4: 0 | M4: Phys/Mag Dmg % | N4: =(B4+30%*K4+20%*K9+15%*H5+15%*H7+K15) -> 1.261
A5: Boss Atk % | B5: 1.008 | F5: Combat Orders (Pally buff) | H5: 0 | J5: Chestnut | K5: 0 | M5: Boss Atk % | N5: =B5+K2+20%*K8+50%*K10+15%*H2+9.6%*H3+G14+K17 -> 1.008
A6: Crit Rate % | B6: 0.696 | F6: Call of the Wild (WH buff) | H6: 0 | J6: Carrot Juice | K6: 0 | M6: Crit Rate % | N6: =B6+30%*K6+20%*K7+10%*K11+K16-B25 -> 0.696
A7: Crit Dmg % | B7: 2.7294 | F7: Evan buff | H7: 0 | J7: Noodle Soup | K7: 0 | M7: Crit rate max | N7: =IF(N6>100%,100%,N6) -> 0.696
A8: Skill % | B8: 2.3 | F8: Lv 200 buff | H8: 0 | J8: Jellyfish | K8: 0 | M8: Crit Dmg % | N8: =B7+30%*K5+30%*H8+20%*K11+G15+K18 -> 2.7294
A9: Final Dmg % | B9: 0.508 | J9: Pork / Snail | K9: 0 | M9: Skill % | N9: =B8 -> 2.3
A10: Max Dmg | B10: 370560099 | F10: Party buffs. Please pick buffs which correspond and benefit with your class | J10: Boss Rush | K10: 0 | M10: Final Dmg % | N10: =(B9+G16+K19) -> 0.508
A11: Current level | B11: 222 | J11: Fever (maxed) | K11: 0 | M11: S3 level modifier | N11: =IF(B11<B12,IF(1-'DMG REDUC (s3phy)'!G9<'DMG REDUC (s3phy)'!G10,'DMG REDUC (s3phy)'!G10,'DMG REDUC (s3phy)'!G9),'DMG REDUC (s3phy)'!G9) -> 0.58040559
A12: Monster level | B12: 200 | J12: Food buffs
A13: Level modifier | B13: ='DMG REDUC (data mined)'!E5/100 -> 0.5674969 | F13: PA/MA Atk % | G13: 0
A14: Boss IED | B14: 0.2 | F14: Boss Atk % | G14: 0
A15: Final IED applied | B15: =(($B$14*(1-$B$16))) -> 0.1952 | F15: Crit Dmg % | G15: 0 | J15: PD / MD% | K15: 0
A16: Total DIR (Def ignore rate) modifier | B16: =1-(1-B17)^1*(1-$B$18)*(1-15/100)^$B$19*(1-25/100)^$B$20*(1-(3/100)*$B$21-(3/100)*$B$22-(4/100)*$B$23) -> 0.024 | D16: =1-(1-B17)^1*(1-$B$18)*(1-15/100)^$B$19*(1-25/100)^$B$20*(1-(3/100)*$B$21-(3/100)*$B$22-(4/100)*$B$23) -> 0.024 | F16: Final Dmg % | G16: 0 | J16: Crit Rate % | K16: 0
B17: 0 | F17: Hyper skill | J17: Boss Atk % | K17: 0
A18: Dir from stats page | B18: 0.024 | D18: =1-(1-$G$19)*(1-$G$20)*(1-$G$21)*(1-$G$22)*(1-$G$23)*(1-$G$24)*(1-$G$25)*(1-$G$26) -> 0.46446726 | J18: Crit Dmg % | K18: 0
A19: Node IED (1=yes) | B19: 0 | F19: Mythic SW IED | G19: 0.04 | J19: Final Dmg % | K19: 0
A20: DS4 Active (1=yes) | B20: 0 | F20: Hat IED | G20: =(8)% -> 0.08 | J20: Additional modifiers | M20: Buffed stats
B21: 0 | F21: Outfit IED | G21: =(8)% -> 0.08
B22: 0 | F22: Glove IED | G22: =(8)% -> 0.08
B23: 0 | F23: Belt IED | G23: =(8)% -> 0.08
F24: Shoe IED | G24: 0.08
A25: Monster Crit Res | B25: 0 | F25: Shoulder IED | G25: 0.08
A26: Input base stats here. Exclude any food buffs & party buffs. Include self buffs. | F26: Cape IED | G26: 0.08
F27: NEW IED breakdown
A30: Stat equivalence | J30: Damage calculator
A31: Current Base Stats | E31: With chosen emblems / potentials | L31: Damage Output Midpoint value | M31: Lowest Crit Damage (CD+0%) | N31: Highest Crit Damage (CD+50%)
A32: Crit Dmg % | B32: 0 | F32: Crit Dmg % | G32: 0.01 | J32: Non-Crit Line (Mobs) | L32: =(N2*(1+N4)*(1+N3)*N9*(1+N10)) -> 635914.69
A33: Boss Atk % | B33: 0 | F33: Boss Atk % | G33: 0 | J33: Crit Line (Mobs) | L33: =L32*(1+25%+N8) -> 2530558.9 | M33: =L32*(1+$N$8) -> 2371580.2 | N33: =L32*(1+50%+$N$8) -> 2689537.6
A34: Phys/Mag Atk % | B34: 0 | F34: PA/MA % | G34: 0 | J34: Average Dmg (Mobs) | L34: =L32*(1-N7)+L33*N7 -> 1954587.1 | M34: =L32*(1-N7)+M33*N7 -> 1843937.9 | N34: =L32*(1-N7)+N33*N7 -> 2065236.2
A35: Phys/Mag Dmg % | B35: 0 | F35: PD/MD % | G35: 0 | J35: Non-Crit Line (Boss) | L35: =(N2*(1+N4)*(1+N3+N9*N5)*N9*(1+N10)) -> 1304594.2
A36: PA/ MA stat | F36: PA/ MA stat | G36: 0 | J36: Crit Line (Boss) | L36: =L35*(1+N8+25%) -> 5191502.2 | M36: =L35*(1+$N$8) -> 4865353.7 | N36: =L35*(1+50%+$N$8) -> 5517650.8
A37: FD % | B37: 0 | F37: FD % | G37: 0
G38: Variance (New vs Old) | J38: Crit Line (Boss, cap) | L38: =IF(L36>B10,B10,L36) -> 5191502.2 | M38: =IF(M36>$B$10,$B$10,M36) -> 4865353.7 | N38: =IF(N36>$B$10,$B$10,N36) -> 5517650.8
A39: Non-Crit Line (Mobs) | B39: =N2*(1+N4)*(1+N3)*N9*(1+N10) -> 635914.69 | F39: =(N2-B36+G36)*(1+N4-B35+G35)*(1+N3-B34+G34)*N9*(1+N10-B37+G37) -> 635914.69 | G39: =+F39/B39-1 -> 0 | J39: Level Difference modifier
A40: Crit Line (Mobs) | B40: =L32*(1+25%+N8) -> 2530558.9 | F40: =L32*(1+25%+(N8-B32+G32)) -> 2536918.1 | G40: =+F40/B40-1 -> 0.0025129416 | J40: Non-Crit Line (Boss) | L40: =L35*$B$13 -> 740353.17
A41: Average Dmg (Mobs) | B41: =L32*(1-N7)+L33*N7 -> 1954587.1 | F41: =F39*(1-N7)+F40*N7 -> 1959013 | G41: =+F41/B41-1 -> 0.0022643996 | J41: Crit Line (Boss) | L41: =L36*$B$13 -> 2946161.4 | M41: =L40*(1+$N$8) -> 2761073.1 | N41: =L40*(1+50%+$N$8) -> 3131249.7
A42: Non-Crit Line (Boss) | B42: =N2*(1+N4)*(1+N3+N9*N5)*N9*(1+N10) -> 1304594.2 | F42: =(N2-B36+G36)*(1+N4-B35+G35)*(1+(N3-B34+G34)+N9*(N5-B33+G33))*N9*(1+N10-B37+G37) -> 1304594.2 | G42: =+F42/B42-1 -> 0 | J42: Crit Line (Boss, cap) | L42: =IF(L41>$B$10,$B$10,L41) -> 2946161.4 | M42: =IF(M41>$B$10,$B$10,M41) -> 2761073.1 | N42: =IF(N41>$B$10,$B$10,N41) -> 3131249.7
...

Sheet Credits
A1: Credits
A2: Paulpork | B2: For Dmg Formula
A3: 櫻櫻美代套子 | B3: For the initial buffed stats calculator
A4: KaitouKiddo | B4: For the initial dmg + emblem calculator
A5: 殘風⎝( OωO)⎠ | B5: For Crit Rate + Cap tests
A6: Whaku | B6: For this spreadsheet. Also similar CR test
A7: S3phy | B7: For updating this spreadsheet
A8: Noodlesoup | B8: For testing and correlating emperical data
A9: Astralmist | B9: For providing datamined defense values and formula
A11: Notes | D11: Last Updated: 30/7/2024
A13: - Phys dmg cap REMOVED AS OF MAY UPDATE
A14: - Make sure not to include duplicate self buffs in both the base stat and party buffs or hyper skill.
A15: - If you want to change "current emblems", then please change your base stats to reflect it first
A16: - Damage formula updated for IED and level modifiers

Sheet Forecast DMG REDUC
A1: Timeline | B1: Values | C1: Forecast | D1: Lower Confidence Bound | E1: Upper Confidence Bound
A2: 1 | B2: -511.26007
A3: 2 | B3: -454.68312
A4: 3 | B4: -396.12787
A5: 4 | B5: -335.64232
A6: 5 | B6: -273.27375
A7: 6 | B7: -209.06872
A8: 7 | B8: -143.07307
A9: 8 | B9: -75.33192
A10: 9 | B10: -5.88967
A11: 10 | B11: 65.21
A12: 11 | B12: 137.92413
A13: 12 | B13: 212.21048
... A250: 249 | B250: 64316.362
A251: 250 | B251: 65201.69 | C251: 65201.69 | D251: 65201.69 | E251: 65201.69
A252: 251 | C252: =_xlfn.FORECAST.ETS(A252,$B$2:$B$251,$A$2:$A$251,1,1) -> 66085.656 | D252: =C252-_xlfn.FORECAST.ETS.CONFINT(A252,$B$2:$B$251,$A$2:$A$251,0.95,1,1) -> 66062.283 | E252: =C252+_xlfn.FORECAST.ETS.CONFINT(A252,$B$2:$B$251,$A$2:$A$251,0.95,1,1) -> 66109.029
A253: 252 | C253: =_xlfn.FORECAST.ETS(A253,$B$2:$B$251,$A$2:$A$251,1,1) -> 66970.957 | D253: =C253-_xlfn.FORECAST.ETS.CONFINT(A253,$B$2:$B$251,$A$2:$A$251,0.95,1,1) -> 66922.849 | E253: =C253+_xlfn.FORECAST.ETS.CONFINT(A253,$B$2:$B$251,$A$2:$A$251,0.95,1,1) -> 67019.065
A254: 253 | C254: =_xlfn.FORECAST.ETS(A254,$B$2:$B$251,$A$2:$A$251,1,1) -> 67856.258 | D254: =C254-_xlfn.FORECAST.ETS.CONFINT(A254,$B$2:$B$251,$A$2:$A$251,0.95,1,1) -> 67776.942 | E254: =C254+_xlfn.FORECAST.ETS.CONFINT(A254,$B$2:$B$251,$A$2:$A$251,0.95,1,1) -> 67935.574
A255: 254 | C255: =_xlfn.FORECAST.ETS(A255,$B$2:$B$251,$A$2:$A$251,1,1) -> 68741.559 | D255: =C255-_xlfn.FORECAST.ETS.CONFINT(A255,$B$2:$B$251,$A$2:$A$251,0.95,1,1) -> 68625.976 | E255: =C255+_xlfn.FORECAST.ETS.CONFINT(A255,$B$2:$B$251,$A$2:$A$251,0.95,1,1) -> 68857.141
A256: 255 | C256: =_xlfn.FORECAST.ETS(A256,$B$2:$B$251,$A$2:$A$251,1,1) -> 69626.859 | D256: =C256-_xlfn.FORECAST.ETS.CONFINT(A256,$B$2:$B$251,$A$2:$A$251,0.95,1,1) -> 69470.647 | E256: =C256+_xlfn.FORECAST.ETS.CONFINT(A256,$B$2:$B$251,$A$2:$A$251,0.95,1,1) -> 69783.071
A257: 256 | C257: =_xlfn.FORECAST.ETS(A257,$B$2:$B$251,$A$2:$A$251,1,1) -> 70512.16 | D257: =C257-_xlfn.FORECAST.ETS.CONFINT(A257,$B$2:$B$251,$A$2:$A$251,0.95,1,1) -> 70311.404 | E257: =C257+_xlfn.FORECAST.ETS.CONFINT(A257,$B$2:$B$251,$A$2:$A$251,0.95,1,1) -> 70712.916
A258: 257 | C258: =_xlfn.FORECAST.ETS(A258,$B$2:$B$251,$A$2:$A$251,1,1) -> 71397.461 | D258: =C258-_xlfn.FORECAST.ETS.CONFINT(A258,$B$2:$B$251,$A$2:$A$251,0.95,1,1) -> 71148.575 | E258: =C258+_xlfn.FORECAST.ETS.CONFINT(A258,$B$2:$B$251,$A$2:$A$251,0.95,1,1) -> 71646.347
A259: 258 | C259: =_xlfn.FORECAST.ETS(A259,$B$2:$B$251,$A$2:$A$251,1,1) -> 72282.762 | D259: =C259-_xlfn.FORECAST.ETS.CONFINT(A259,$B$2:$B$251,$A$2:$A$251,0.95,1,1) -> 71982.413 | E259: =C259+_xlfn.FORECAST.ETS.CONFINT(A259,$B$2:$B$251,$A$2:$A$251,0.95,1,1) -> 72583.111
A260: 259 | C260: =_xlfn.FORECAST.ETS(A260,$B$2:$B$251,$A$2:$A$251,1,1) -> 73168.062 | D260: =C260-_xlfn.FORECAST.ETS.CONFINT(A260,$B$2:$B$251,$A$2:$A$251,0.95,1,1) -> 72813.124 | E260: =C260+_xlfn.FORECAST.ETS.CONFINT(A260,$B$2:$B$251,$A$2:$A$251,0.95,1,1) -> 73523.001
A261: 260 | C261: =_xlfn.FORECAST.ETS(A261,$B$2:$B$251,$A$2:$A$251,1,1) -> 74053.363 | D261: =C261-_xlfn.FORECAST.ETS.CONFINT(A261,$B$2:$B$251,$A$2:$A$251,0.95,1,1) -> 73640.879 | E261: =C261+_xlfn.FORECAST.ETS.CONFINT(A261,$B$2:$B$251,$A$2:$A$251,0.95,1,1) -> 74465.848
A262: 261 | C262: =_xlfn.FORECAST.ETS(A262,$B$2:$B$251,$A$2:$A$251,1,1) -> 74938.664 | D262: =C262-_xlfn.FORECAST.ETS.CONFINT(A262,$B$2:$B$251,$A$2:$A$251,0.95,1,1) -> 74465.823 | E262: =C262+_xlfn.FORECAST.ETS.CONFINT(A262,$B$2:$B$251,$A$2:$A$251,0.95,1,1) -> 75411.505
A263: 262 | C263: =_xlfn.FORECAST.ETS(A263,$B$2:$B$251,$A$2:$A$251,1,1) -> 75823.965 | D263: =C263-_xlfn.FORECAST.ETS.CONFINT(A263,$B$2:$B$251,$A$2:$A$251,0.95,1,1) -> 75288.083 | E263: =C263+_xlfn.FORECAST.ETS.CONFINT(A263,$B$2:$B$251,$A$2:$A$251,0.95,1,1) -> 76359.846
... A314: 313 | C314: =_xlfn.FORECAST.ETS(A314,$B$2:$B$251,$A$2:$A$251,1,1) -> 120974.3 | D314: =C314-_xlfn.FORECAST.ETS.CONFINT(A314,$B$2:$B$251,$A$2:$A$251,0.95,1,1) -> 114835.64 | E314: =C314+_xlfn.FORECAST.ETS.CONFINT(A314,$B$2:$B$251,$A$2:$A$251,0.95,1,1) -> 127112.97

Sheet DMG REDUC (data mined)
A1: Level | B1: DefenseRating | E1: Your Level | F1: Target Level | H1: Formula | O1: TargetDefense | P1: YourDR | Q1: Target Level | R1: DamageReduction% | S1: TotalDR (Boss) | T1: Target Level | U1: DamageReduction% | V1: TotalDR (Mob)
A2: 1 | B2: 292 | D2: User Input -> | E2: =+'Damage Calculator'!B11 -> 222 | F2: =+'Damage Calculator'!B12 -> 200 | H2: DamageReduction% = | I2: TargetDefense / | O2: =VLOOKUP(F2,A:B,2,FALSE) -> 32420 | P2: =VLOOKUP(E2,A:B,2,FALSE) -> 42539 | Q2: 1 | R2: =VLOOKUP(Q2,$A:$B,2,FALSE)/S2*100 -> 0.6817492 | S2: =(VLOOKUP($E$2,$A:$B,2,FALSE)+VLOOKUP(Q2,$A:$B,2,FALSE)) -> 42831 | T2: 1 | U2: =(VLOOKUP(T2,$A:$B,2,FALSE)/9)/V2*100 -> 0.075749911 | V2: =(VLOOKUP($E$2,$A:$B,2,FALSE)+VLOOKUP(Q2,$A:$B,2,FALSE)) -> 42831
A3: 2 | B3: 385 | E3: Damage Reduction % | F3: TotalDR | I3: (YourDefenseRating + TargetDefenseRating) | Q3: 2 | R3: =VLOOKUP(Q3,$A:$B,2,FALSE)/S3*100 -> 0.89693412 | S3: =(VLOOKUP($E$2,$A:$B,2,FALSE)+VLOOKUP(Q3,$A:$B,2,FALSE)) -> 42924 | T3: 2 | U3: =(VLOOKUP(T3,$A:$B,2,FALSE)/9)/V3*100 -> 0.099659346 | V3: =(VLOOKUP($E$2,$A:$B,2,FALSE)+VLOOKUP(Q3,$A:$B,2,FALSE)) -> 42924
A4: 3 | B4: 478 | E4: =VLOOKUP(F2,$A:$B,2,FALSE)/F4*100 -> 43.25031 | F4: =(VLOOKUP(F2,A:B,2,FALSE)+VLOOKUP(E2,A:B,2,FALSE)) -> 74959 | H4: Generally, TargetDefense is same as its DefenseRating unless manually overwritten | Q4: 3 | R4: =VLOOKUP(Q4,$A:$B,2,FALSE)/S4*100 -> 1.1111886 | S4: =(VLOOKUP($E$2,$A:$B,2,FALSE)+VLOOKUP(Q4,$A:$B,2,FALSE)) -> 43017 | T4: 3 | U4: =(VLOOKUP(T4,$A:$B,2,FALSE)/9)/V4*100 -> 0.1234654 | V4: =(VLOOKUP($E$2,$A:$B,2,FALSE)+VLOOKUP(Q4,$A:$B,2,FALSE)) -> 43017
A5: 4 | B5: 572 | E5: =100-E4 -> 56.74969 | H5: Some exceptions eg. Lotus Phase 1, Guild Dungeon etc | Q5: 4 | R5: =VLOOKUP(Q5,$A:$B,2,FALSE)/S5*100 -> 1.3268075 | S5: =(VLOOKUP($E$2,$A:$B,2,FALSE)+VLOOKUP(Q5,$A:$B,2,FALSE)) -> 43111 | T5: 4 | U5: =(VLOOKUP(T5,$A:$B,2,FALSE)/9)/V5*100 -> 0.14742306 | V5: =(VLOOKUP($E$2,$A:$B,2,FALSE)+VLOOKUP(Q5,$A:$B,2,FALSE)) -> 43111
A6: 5 | B6: 666 | Q6: 5 | R6: =VLOOKUP(Q6,$A:$B,2,FALSE)/S6*100 -> 1.5414883 | S6: =(VLOOKUP($E$2,$A:$B,2,FALSE)+VLOOKUP(Q6,$A:$B,2,FALSE)) -> 43205 | T6: 5 | U6: =(VLOOKUP(T6,$A:$B,2,FALSE)/9)/V6*100 -> 0.17127647 | V6: =(VLOOKUP($E$2,$A:$B,2,FALSE)+VLOOKUP(Q6,$A:$B,2,FALSE)) -> 43205
A7: 6 | B7: 760 | Q7: 6 | R7: =VLOOKUP(Q7,$A:$B,2,FALSE)/S7*100 -> 1.7552368 | S7: =(VLOOKUP($E$2,$A:$B,2,FALSE)+VLOOKUP(Q7,$A:$B,2,FALSE)) -> 43299 | T7: 6 | U7: =(VLOOKUP(T7,$A:$B,2,FALSE)/9)/V7*100 -> 0.19502632 | V7: =(VLOOKUP($E$2,$A:$B,2,FALSE)+VLOOKUP(Q7,$A:$B,2,FALSE)) -> 43299
A8: 7 | B8: 853 | Q8: 7 | R8: =VLOOKUP(Q8,$A:$B,2,FALSE)/S8*100 -> 1.9658001 | S8: =(VLOOKUP($E$2,$A:$B,2,FALSE)+VLOOKUP(Q8,$A:$B,2,FALSE)) -> 43392 | T8: 7 | U8: =(VLOOKUP(T8,$A:$B,2,FALSE)/9)/V8*100 -> 0.21842224 | V8: =(VLOOKUP($E$2,$A:$B,2,FALSE)+VLOOKUP(Q8,$A:$B,2,FALSE)) -> 43392
A9: 8 | B9: 948 | Q9: 8 | R9: =VLOOKUP(Q9,$A:$B,2,FALSE)/S9*100 -> 2.1799618 | S9: =(VLOOKUP($E$2,$A:$B,2,FALSE)+VLOOKUP(Q9,$A:$B,2,FALSE)) -> 43487 | T9: 8 | U9: =(VLOOKUP(T9,$A:$B,2,FALSE)/9)/V9*100 -> 0.24221798 | V9: =(VLOOKUP($E$2,$A:$B,2,FALSE)+VLOOKUP(Q9,$A:$B,2,FALSE)) -> 43487
A10: 9 | B10: 1042 | Q10: 9 | R10: =VLOOKUP(Q10,$A:$B,2,FALSE)/S10*100 -> 2.3909502 | S10: =(VLOOKUP($E$2,$A:$B,2,FALSE)+VLOOKUP(Q10,$A:$B,2,FALSE)) -> 43581 | T10: 9 | U10: =(VLOOKUP(T10,$A:$B,2,FALSE)/9)/V10*100 -> 0.26566113 | V10: =(VLOOKUP($E$2,$A:$B,2,FALSE)+VLOOKUP(Q10,$A:$B,2,FALSE)) -> 43581
A11: 10 | B11: 1136 | Q11: 10 | R11: =VLOOKUP(Q11,$A:$B,2,FALSE)/S11*100 -> 2.6010303 | S11: =(VLOOKUP($E$2,$A:$B,2,FALSE)+VLOOKUP(Q11,$A:$B,2,FALSE)) -> 43675 | T11: 10 | U11: =(VLOOKUP(T11,$A:$B,2,FALSE)/9)/V11*100 -> 0.28900337 | V11: =(VLOOKUP($E$2,$A:$B,2,FALSE)+VLOOKUP(Q11,$A:$B,2,FALSE)) -> 43675
A12: 11 | B12: 1231 | Q12: 11 | R12: =VLOOKUP(Q12,$A:$B,2,FALSE)/S12*100 -> 2.8124286 | S12: =(VLOOKUP($E$2,$A:$B,2,FALSE)+VLOOKUP(Q12,$A:$B,2,FALSE)) -> 43770 | T12: 11 | U12: =(VLOOKUP(T12,$A:$B,2,FALSE)/9)/V12*100 -> 0.31249207 | V12: =(VLOOKUP($E$2,$A:$B,2,FALSE)+VLOOKUP(Q12,$A:$B,2,FALSE)) -> 43770
A13: 12 | B13: 1325 | Q13: 12 | R13: =VLOOKUP(Q13,$A:$B,2,FALSE)/S13*100 -> 3.0207003 | S13: =(VLOOKUP($E$2,$A:$B,2,FALSE)+VLOOKUP(Q13,$A:$B,2,FALSE)) -> 43864 | T13: 12 | U13: =(VLOOKUP(T13,$A:$B,2,FALSE)/9)/V13*100 -> 0.33563337 | V13: =(VLOOKUP($E$2,$A:$B,2,FALSE)+VLOOKUP(Q13,$A:$B,2,FALSE)) -> 43864
A14: 13 | B14: 1420 | Q14: 13 | R14: =VLOOKUP(Q14,$A:$B,2,FALSE)/S14*100 -> 3.2302828 | S14: =(VLOOKUP($E$2,$A:$B,2,FALSE)+VLOOKUP(Q14,$A:$B,2,FALSE)) -> 43959 | T14: 13 | U14: =(VLOOKUP(T14,$A:$B,2,FALSE)/9)/V14*100 -> 0.35892031 | V14: =(VLOOKUP($E$2,$A:$B,2,FALSE)+VLOOKUP(Q14,$A:$B,2,FALSE)) -> 43959
A15: 14 | B15: 1515 | Q15: 14 | R15: =VLOOKUP(Q15,$A:$B,2,FALSE)/S15*100 -> 3.4389613 | S15: =(VLOOKUP($E$2,$A:$B,2,FALSE)+VLOOKUP(Q15,$A:$B,2,FALSE)) -> 44054 | T15: 14 | U15: =(VLOOKUP(T15,$A:$B,2,FALSE)/9)/V15*100 -> 0.38210681 | V15: =(VLOOKUP($E$2,$A:$B,2,FALSE)+VLOOKUP(Q15,$A:$B,2,FALSE)) -> 44054
A16: 15 | B16: 1610 | Q16: 15 | R16: =VLOOKUP(Q16,$A:$B,2,FALSE)/S16*100 -> 3.6467417 | S16: =(VLOOKUP($E$2,$A:$B,2,FALSE)+VLOOKUP(Q16,$A:$B,2,FALSE)) -> 44149 | T16: 15 | U16: =(VLOOKUP(T16,$A:$B,2,FALSE)/9)/V16*100 -> 0.40519352 | V16: =(VLOOKUP($E$2,$A:$B,2,FALSE)+VLOOKUP(Q16,$A:$B,2,FALSE)) -> 44149
A17: 16 | B17: 1705 | Q17: 16 | R17: =VLOOKUP(Q17,$A:$B,2,FALSE)/S17*100 -> 3.8536299 | S17: =(VLOOKUP($E$2,$A:$B,2,FALSE)+VLOOKUP(Q17,$A:$B,2,FALSE)) -> 44244 | T17: 16 | U17: =(VLOOKUP(T17,$A:$B,2,FALSE)/9)/V17*100 -> 0.4281811 | V17: =(VLOOKUP($E$2,$A:$B,2,FALSE)+VLOOKUP(Q17,$A:$B,2,FALSE)) -> 44244
... A251: 250 | B251: 62183 | Q251: 250 | R251: =VLOOKUP(Q251,$A:$B,2,FALSE)/S251*100 -> 59.379118 | S251: =(VLOOKUP($E$2,$A:$B,2,FALSE)+VLOOKUP(Q251,$A:$B,2,FALSE)) -> 104722 | T251: 250 | U251: =(VLOOKUP(T251,$A:$B,2,FALSE)/9)/V251*100 -> 6.5976798 | V251: =(VLOOKUP($E$2,$A:$B,2,FALSE)+VLOOKUP(Q251,$A:$B,2,FALSE)) -> 104722
A252: 251 | B252: 65201.69 | C252: 65201.69 | D252: 65201.69 | Q252: =+Q251+1 -> 251 | R252: =VLOOKUP(Q252,$A:$B,2,FALSE)/S252*100 -> 60.517238 | S252: =(VLOOKUP($E$2,$A:$B,2,FALSE)+VLOOKUP(Q252,$A:$B,2,FALSE)) -> 107740.69 | T252: 251 | U252: =(VLOOKUP(T252,$A:$B,2,FALSE)/9)/V252*100 -> 6.7241376 | V252: =(VLOOKUP($E$2,$A:$B,2,FALSE)+VLOOKUP(Q252,$A:$B,2,FALSE)) -> 107740.69
A253: =A252+1 -> 252 | B253: 66085.656 | C253: 66062.283 | D253: 66109.029 | Q253: =+Q252+1 -> 252 | R253: =VLOOKUP(Q253,$A:$B,2,FALSE)/S253*100 -> 60.838541 | S253: =(VLOOKUP($E$2,$A:$B,2,FALSE)+VLOOKUP(Q253,$A:$B,2,FALSE)) -> 108624.66 | T253: 252 | U253: =(VLOOKUP(T253,$A:$B,2,FALSE)/9)/V253*100 -> 6.7598379 | V253: =(VLOOKUP($E$2,$A:$B,2,FALSE)+VLOOKUP(Q253,$A:$B,2,FALSE)) -> 108624.66
A254: =A253+1 -> 253 | B254: 66970.957 | C254: 66922.849 | D254: 67019.065 | Q254: =+Q253+1 -> 253 | R254: =VLOOKUP(Q254,$A:$B,2,FALSE)/S254*100 -> 61.15513 | S254: =(VLOOKUP($E$2,$A:$B,2,FALSE)+VLOOKUP(Q254,$A:$B,2,FALSE)) -> 109509.96 | T254: 253 | U254: =(VLOOKUP(T254,$A:$B,2,FALSE)/9)/V254*100 -> 6.7950145 | V254: =(VLOOKUP($E$2,$A:$B,2,FALSE)+VLOOKUP(Q254,$A:$B,2,FALSE)) -> 109509.96
A255: =A254+1 -> 254 | B255: 67856.258 | C255: 67776.942 | D255: 67935.574 | Q255: =+Q254+1 -> 254 | R255: =VLOOKUP(Q255,$A:$B,2,FALSE)/S255*100 -> 61.466642 | S255: =(VLOOKUP($E$2,$A:$B,2,FALSE)+VLOOKUP(Q255,$A:$B,2,FALSE)) -> 110395.26 | T255: 254 | U255: =(VLOOKUP(T255,$A:$B,2,FALSE)/9)/V255*100 -> 6.8296269 | V255: =(VLOOKUP($E$2,$A:$B,2,FALSE)+VLOOKUP(Q255,$A:$B,2,FALSE)) -> 110395.26
A256: =A255+1 -> 255 | B256: 68741.559 | C256: 68625.976 | D256: 68857.141 | Q256: =+Q255+1 -> 255 | R256: =VLOOKUP(Q256,$A:$B,2,FALSE)/S256*100 -> 61.773197 | S256: =(VLOOKUP($E$2,$A:$B,2,FALSE)+VLOOKUP(Q256,$A:$B,2,FALSE)) -> 111280.56 | T256: 255 | U256: =(VLOOKUP(T256,$A:$B,2,FALSE)/9)/V256*100 -> 6.8636885 | V256: =(VLOOKUP($E$2,$A:$B,2,FALSE)+VLOOKUP(Q256,$A:$B,2,FALSE)) -> 111280.56
A257: =A256+1 -> 256 | B257: 69626.859 | C257: 69470.647 | D257: 69783.071 | Q257: =+Q256+1 -> 256 | R257: =VLOOKUP(Q257,$A:$B,2,FALSE)/S257*100 -> 62.074913 | S257: =(VLOOKUP($E$2,$A:$B,2,FALSE)+VLOOKUP(Q257,$A:$B,2,FALSE)) -> 112165.86 | T257: 256 | U257: =(VLOOKUP(T257,$A:$B,2,FALSE)/9)/V257*100 -> 6.8972125 | V257: =(VLOOKUP($E$2,$A:$B,2,FALSE)+VLOOKUP(Q257,$A:$B,2,FALSE)) -> 112165.86
A258: =A257+1 -> 257 | B258: 70512.16 | C258: 70311.404 | D258: 70712.916 | Q258: =+Q257+1 -> 257 | R258: =VLOOKUP(Q258,$A:$B,2,FALSE)/S258*100 -> 62.371903 | S258: =(VLOOKUP($E$2,$A:$B,2,FALSE)+VLOOKUP(Q258,$A:$B,2,FALSE)) -> 113051.16 | T258: 257 | U258: =(VLOOKUP(T258,$A:$B,2,FALSE)/9)/V258*100 -> 6.9302115 | V258: =(VLOOKUP($E$2,$A:$B,2,FALSE)+VLOOKUP(Q258,$A:$B,2,FALSE)) -> 113051.16
A259: =A258+1 -> 258 | B259: 71397.461 | C259: 71148.575 | D259: 71646.347 | Q259: =+Q258+1 -> 258 | R259: =VLOOKUP(Q259,$A:$B,2,FALSE)/S259*100 -> 62.664278 | S259: =(VLOOKUP($E$2,$A:$B,2,FALSE)+VLOOKUP(Q259,$A:$B,2,FALSE)) -> 113936.46 | T259: 258 | U259: =(VLOOKUP(T259,$A:$B,2,FALSE)/9)/V259*100 -> 6.9626976 | V259: =(VLOOKUP($E$2,$A:$B,2,FALSE)+VLOOKUP(Q259,$A:$B,2,FALSE)) -> 113936.46
A260: =A259+1 -> 259 | B260: 72282.762 | C260: 71982.413 | D260: 72583.111 | Q260: =+Q259+1 -> 259 | R260: =VLOOKUP(Q260,$A:$B,2,FALSE)/S260*100 -> 62.952145 | S260: =(VLOOKUP($E$2,$A:$B,2,FALSE)+VLOOKUP(Q260,$A:$B,2,FALSE)) -> 114821.76 | T260: 259 | U260: =(VLOOKUP(T260,$A:$B,2,FALSE)/9)/V260*100 -> 6.9946828 | V260: =(VLOOKUP($E$2,$A:$B,2,FALSE)+VLOOKUP(Q260,$A:$B,2,FALSE)) -> 114821.76
A261: =A260+1 -> 260 | B261: 73168.062 | C261: 72813.124 | D261: 73523.001 | Q261: =+Q260+1 -> 260 | R261: =VLOOKUP(Q261,$A:$B,2,FALSE)/S261*100 -> 63.235606 | S261: =(VLOOKUP($E$2,$A:$B,2,FALSE)+VLOOKUP(Q261,$A:$B,2,FALSE)) -> 115707.06 | T261: 260 | U261: =(VLOOKUP(T261,$A:$B,2,FALSE)/9)/V261*100 -> 7.0261785 | V261: =(VLOOKUP($E$2,$A:$B,2,FALSE)+VLOOKUP(Q261,$A:$B,2,FALSE)) -> 115707.06
A262: =A261+1 -> 261 | B262: 74053.363 | C262: 73640.879 | D262: 74465.848 | Q262: =+Q261+1 -> 261 | R262: =VLOOKUP(Q262,$A:$B,2,FALSE)/S262*100 -> 63.514763 | S262: =(VLOOKUP($E$2,$A:$B,2,FALSE)+VLOOKUP(Q262,$A:$B,2,FALSE)) -> 116592.36 | T262: 261 | U262: =(VLOOKUP(T262,$A:$B,2,FALSE)/9)/V262*100 -> 7.0571959 | V262: =(VLOOKUP($E$2,$A:$B,2,FALSE)+VLOOKUP(Q262,$A:$B,2,FALSE)) -> 116592.36
A263: =A262+1 -> 262 | B263: 74938.664 | C263: 74465.823 | D263: 75411.505 | Q263: =+Q262+1 -> 262 | R263: =VLOOKUP(Q263,$A:$B,2,FALSE)/S263*100 -> 63.789712 | S263: =(VLOOKUP($E$2,$A:$B,2,FALSE)+VLOOKUP(Q263,$A:$B,2,FALSE)) -> 117477.66 | T263: 262 | U263: =(VLOOKUP(T263,$A:$B,2,FALSE)/9)/V263*100 -> 7.0877458 | V263: =(VLOOKUP($E$2,$A:$B,2,FALSE)+VLOOKUP(Q263,$A:$B,2,FALSE)) -> 117477.66
A264: =A263+1 -> 263 | B264: 75823.965 | C264: 75288.083 | D264: 76359.846 | Q264: =+Q263+1 -> 263 | R264: =VLOOKUP(Q264,$A:$B,2,FALSE)/S264*100 -> 64.060549 | S264: =(VLOOKUP($E$2,$A:$B,2,FALSE)+VLOOKUP(Q264,$A:$B,2,FALSE)) -> 118362.96 | T264: 263 | U264: =(VLOOKUP(T264,$A:$B,2,FALSE)/9)/V264*100 -> 7.1178388 | V264: =(VLOOKUP($E$2,$A:$B,2,FALSE)+VLOOKUP(Q264,$A:$B,2,FALSE)) -> 118362.96
... A301: =A300+1 -> 300 | B301: 108580.09 | C301: 104355.19 | D301: 112804.99 | Q301: =+Q300+1 -> 300 | R301: =VLOOKUP(Q301,$A:$B,2,FALSE)/S301*100 -> 71.850678 | S301: =(VLOOKUP($E$2,$A:$B,2,FALSE)+VLOOKUP(Q301,$A:$B,2,FALSE)) -> 151119.09 | T301: 300 | U301: =(VLOOKUP(T301,$A:$B,2,FALSE)/9)/V301*100 -> 7.9834087 | V301: =(VLOOKUP($E$2,$A:$B,2,FALSE)+VLOOKUP(Q301,$A:$B,2,FALSE)) -> 151119.09
B302: 109465.39 | C302: 105111.82 | D302: 113818.97
B303: 110350.69 | C303: 105867.16 | D303: 114834.23
B304: 111236 | C304: 106621.23 | D304: 115850.76
B305: 112121.3 | C305: 107374.05 | D305: 116868.54
B306: 113006.6 | C306: 108125.63 | D306: 117887.56
B307: 113891.9 | C307: 108875.97 | D307: 118907.82
B308: 114777.2 | C308: 109625.1 | D308: 119929.3
B309: 115662.5 | C309: 110373.01 | D309: 120951.99
...

Sheet DMG REDUC (s3phy)
B2: Monster lvl | C2: lvl diff count | D2: Modifier % | F2: Workings
B3: 1 | C3: =IF(('Damage Calculator'!$B$11-B3)<0,0,('Damage Calculator'!$B$11-B3)+1) -> 222 | D3: 1 | F3: Ave per lvl | G3: =($D$3-$G$10)/$G$4 -> 0.021741069
B4: 10 | C4: =IF(('Damage Calculator'!$B$11-B4)<0,0,('Damage Calculator'!$B$11-B4)) -> 212 | D4: =IF(C4=0,$G$10,(D3-$G$3)) -> 0.97825893 | F4: Count | G4: =COUNTIF(C3:C31,">0") -> 23
B5: =B4+10 -> 20 | C5: =IF(('Damage Calculator'!$B$11-B5)<0,0,('Damage Calculator'!$B$11-B5)) -> 202 | D5: =IF(C5=0,$G$10,(D4-$G$3)) -> 0.95651786 | F5: Rounding | G5: =ROUNDDOWN('Damage Calculator'!$B$12,-1) -> 200
B6: =B5+10 -> 30 | C6: =IF(('Damage Calculator'!$B$11-B6)<0,0,('Damage Calculator'!$B$11-B6)) -> 192 | D6: =IF(C6=0,$G$10,(D5-$G$3)) -> 0.93477679 | F6: Lvl difference | G6: =ABS('Damage Calculator'!$B$11-'Damage Calculator'!$B$12) -> 22
B7: =B6+10 -> 40 | C7: =IF(('Damage Calculator'!$B$11-B7)<0,0,('Damage Calculator'!$B$11-B7)) -> 182 | D7: =IF(C7=0,$G$10,(D6-$G$3)) -> 0.91303573 | F7: Forecast | G7: =IF(G6=0,$G$10,IF(G6=('Damage Calculator'!$B$11-1),100%,_xlfn.FORECAST.LINEAR($G$6,$D$3:$D$34,$C$3:$C$34))) -> 0.55840559
B8: =B7+10 -> 50 | C8: =IF(('Damage Calculator'!$B$11-B8)<0,0,('Damage Calculator'!$B$11-B8)) -> 172 | D8: =IF(C8=0,$G$10,(D7-$G$3)) -> 0.89129466 | F8: Specific level mod | G8: =+IF('Damage Calculator'!$B$11-'Damage Calculator'!$B$12<=70,('Damage Calculator'!$B$11-'Damage Calculator'!$B$12)/1000,0) -> 0.022
B9: =B8+10 -> 60 | C9: =IF(('Damage Calculator'!$B$11-B9)<0,0,('Damage Calculator'!$B$11-B9)) -> 162 | D9: =IF(C9=0,$G$10,(D8-$G$3)) -> 0.86955359 | F9: Total modifier | G9: =G7+G8 -> 0.58040559
B10: =B9+10 -> 70 | C10: =IF(('Damage Calculator'!$B$11-B10)<0,0,('Damage Calculator'!$B$11-B10)) -> 152 | D10: =IF(C10=0,$G$10,(D9-$G$3)) -> 0.84781252 | F10: Seed | G10: 0.49995542
B11: =B10+10 -> 80 | C11: =IF(('Damage Calculator'!$B$11-B11)<0,0,('Damage Calculator'!$B$11-B11)) -> 142 | D11: =IF(C11=0,$G$10,(D10-$G$3)) -> 0.82607145
B12: =B11+10 -> 90 | C12: =IF(('Damage Calculator'!$B$11-B12)<0,0,('Damage Calculator'!$B$11-B12)) -> 132 | D12: =IF(C12=0,$G$10,(D11-$G$3)) -> 0.80433038
B13: =B12+10 -> 100 | C13: =IF(('Damage Calculator'!$B$11-B13)<0,0,('Damage Calculator'!$B$11-B13)) -> 122 | D13: =IF(C13=0,$G$10,(D12-$G$3)) -> 0.78258931
B14: =B13+10 -> 110 | C14: =IF(('Damage Calculator'!$B$11-B14)<0,0,('Damage Calculator'!$B$11-B14)) -> 112 | D14: =IF(C14=0,$G$10,(D13-$G$3)) -> 0.76084825
B15: =B14+10 -> 120 | C15: =IF(('Damage Calculator'!$B$11-B15)<0,0,('Damage Calculator'!$B$11-B15)) -> 102 | D15: =IF(C15=0,$G$10,(D14-$G$3)) -> 0.73910718
B19: =B15+10 -> 130 | C19: =IF(('Damage Calculator'!$B$11-B19)<0,0,('Damage Calculator'!$B$11-B19)) -> 92 | D19: =IF(C19=0,$G$10,(D15-$G$3)) -> 0.71736611
B20: =B19+10 -> 140 | C20: =IF(('Damage Calculator'!$B$11-B20)<0,0,('Damage Calculator'!$B$11-B20)) -> 82 | D20: =IF(C20=0,$G$10,(D19-$G$3)) -> 0.69562504
B21: =B20+10 -> 150 | C21: =IF(('Damage Calculator'!$B$11-B21)<0,0,('Damage Calculator'!$B$11-B21)) -> 72 | D21: =IF(C21=0,$G$10,(D20-$G$3)) -> 0.67388397
B22: =B21+10 -> 160 | C22: =IF(('Damage Calculator'!$B$11-B22)<0,0,('Damage Calculator'!$B$11-B22)) -> 62 | D22: =IF(C22=0,$G$10,(D21-$G$3)) -> 0.6521429
B23: =B22+10 -> 170 | C23: =IF(('Damage Calculator'!$B$11-B23)<0,0,('Damage Calculator'!$B$11-B23)) -> 52 | D23: =IF(C23=0,$G$10,(D22-$G$3)) -> 0.63040183
B24: =B23+10 -> 180 | C24: =IF(('Damage Calculator'!$B$11-B24)<0,0,('Damage Calculator'!$B$11-B24)) -> 42 | D24: =IF(C24=0,$G$10,(D23-$G$3)) -> 0.60866077
B25: =B24+10 -> 190 | C25: =IF(('Damage Calculator'!$B$11-B25)<0,0,('Damage Calculator'!$B$11-B25)) -> 32 | D25: =IF(C25=0,$G$10,(D24-$G$3)) -> 0.5869197
B26: =B25+10 -> 200 | C26: =IF(('Damage Calculator'!$B$11-B26)<0,0,('Damage Calculator'!$B$11-B26)) -> 22 | D26: =IF(C26=0,$G$10,(D25-$G$3)) -> 0.56517863
B27: =B26+10 -> 210 | C27: =IF(('Damage Calculator'!$B$11-B27)<0,0,('Damage Calculator'!$B$11-B27)) -> 12 | D27: =IF(C27=0,$G$10,(D26-$G$3)) -> 0.54343756
B28: =B27+10 -> 220 | C28: =IF(('Damage Calculator'!$B$11-B28)<0,0,('Damage Calculator'!$B$11-B28)) -> 2 | D28: =IF(C28=0,$G$10,(D27-$G$3)) -> 0.52169649
B29: =B28+10 -> 230 | C29: =IF(('Damage Calculator'!$B$11-B29)<0,0,('Damage Calculator'!$B$11-B29)) -> 0 | D29: =IF(C29=0,$G$10,(D28-$G$3)) -> 0.49995542
B30: =B29+10 -> 240 | C30: =IF(('Damage Calculator'!$B$11-B30)<0,0,('Damage Calculator'!$B$11-B30)) -> 0 | D30: =IF(C30=0,$G$10,(D29-$G$3)) -> 0.49995542
B31: =B30+10 -> 250 | C31: =IF(('Damage Calculator'!$B$11-B31)<0,0,('Damage Calculator'!$B$11-B31)) -> 0 | D31: =IF(C31=0,$G$10,(D30-$G$3)) -> 0.49995542
B32: =B31+10 -> 260 | C32: =IF(('Damage Calculator'!$B$11-B32)<0,0,('Damage Calculator'!$B$11-B32)) -> 0 | D32: =IF(C32=0,$G$10,(D31-$G$3)) -> 0.49995542
B34: =B32+10 -> 270 | C34: =IF(('Damage Calculator'!$B$11-B34)<0,0,('Damage Calculator'!$B$11-B34)) -> 0 | D34: =IF(C34=0,$G$10,(D32-$G$3)) -> 0.49995542
B35: =B34+10 -> 280 | C35: =IF(('Damage Calculator'!$B$11-B35)<0,0,('Damage Calculator'!$B$11-B35)) -> 0 | D35: =IF(C35=0,$G$10,(D34-$G$3)) -> 0.49995542
B36: =B35+10 -> 290 | C36: =IF(('Damage Calculator'!$B$11-B36)<0,0,('Damage Calculator'!$B$11-B36)) -> 0 | D36: =IF(C36=0,$G$10,(D35-$G$3)) -> 0.49995542
B37: =B36+10 -> 300 | C37: =IF(('Damage Calculator'!$B$11-B37)<0,0,('Damage Calculator'!$B$11-B37)) -> 0 | D37: =IF(C37=0,$G$10,(D36-$G$3)) -> 0.49995542

Sheet Damage Formula
H7: THE REAL DAMAGE FORMULA
H9: I'm glad to share my result in research the damage formula. the mystery formula is:
H11: Damage to normal mob = ATK * skill% * (1 + DMG%) * (1 + FD%) * (1 + ATK%)
H13: Damage to Bosses = ATK * skill% * (1 + DMG%) * (1 + FD%) * (1 + ATK% + skill% * BossATK%)
H15: Critical Damage = Non-critical damage * (1 + Critical Damage% + 0.2)
H17: The BossATK% part makes no sense, but it certainly works this way. It's hard to explain how I obtain this formula, so I'll just leave all the data I collected here.
H19: https://docs.google.com/spreadsheets/d/1FisXW3NUeIJCVxWo8wi68XHMSFVglOjf3ji-zx_85Nk/edit#gid=1964636317
H21: The improvement of different BossATK% is affected by both BossATK% and skill%. We found that it is calculated by skill% * BossATK%. Also, they are added to ATK%.
H23: For the FD%, sum up all final damage you have to get the total FD%. Thanks to u/FR0STM0UI2NE for doing the test. If you are curious about the details, here's the post.
H25: https://www.reddit.com/r/MapleStoryM/comments/fyfklm/a_test_on_the_effect_of_final_dmg_and_the/
H27: There are some other stuff I found during this research. You can find them in this slide.
H29: https://hackmd.io/@pzpsaFv3SXS74AStOrLFsA/rJkkmEqv8?type=slide#/
... H56: It doesn't work out as cleanly, since BD lines are much higher than any %ATT lines you can get, and Reboot gives you a lot of %Damage.
H59: Let: | I59: https://www.reddit.com/r/Maplestory/comments/iwjbts/how_does_crit_damage_work_exactly/#:~:text=You%20have%20to%20remember%20that,damage%20to%20obtain%20basic%20damage.
H61: A = Maximum Base Damage which is a function of Attack, Stats, and Weapon Multiplier
H63: B = %Boss Damage in Stats UI
H65: C = %Crit Damage in Stats UI
H67: D = %Damage in Stats UI
H69: F = %Final Damage in Stats UI
H71: W = Weapon Mastery (Usually 70%)
H73: S = Skill Damage
H75: General Formula: Actual Range vs Bosses
H77: Maximum Critical Damage = A×(1+B+D)×(1.5+C)×(1+F)
H79: Minimum Critical Damage = A×W×(1+B+D)×(1.2+C)×(1+F)
H81: Multiply the above with Skill Damage for actual damage per line of a particular skill.
H83: Drop B if facing normal mobs

Sheet Change Log
A1: Date | B1: Changes
A2: May 26th 2020 | B2: Damage & Emblem calculator released
A3: May 26th 2020 | B3: Fixed issue where adding BA% in hyperstats didn't do anything
A4: July 14th 2020 | B4: Changed the way crit res behaves as crit rate hard caps at 100%
A5: August 3rd 2020 | B5: Added Wild Hunter buff and Lv 200 buff options, removed Pink Bean buffs
A6: August 9th 2020 | B6: Fixed a minor issue with crit res calculation where abnormal 0% crit rate was applying at times. Added damage cap calculations
A7: June 14th 2023 | B7: Updated with damage formula factoring in level modifiers and IED
A8: June 17th 2023 | B8: Further enhanced damage modifier interpolation methodology with Forecast function, fixed negative level interpolation, increased base level to 300
A9: July 4th 2024 | B9: Updated damage modifier with constant value adjustment based on level difference of up to 70, i.e. 270 (max level cap) - 200 (boss level)
A10: July 30th 2024 | B10: Updated damage modifier based on data mined values, extrapolated to level 270
